<?xml version="1.0"?>
<robot xmlns:xacro="http://ros.org/wiki/xacro">
  <xacro:include filename="$(find abb_resources)/urdf/common_materials.xacro"/>

  <xacro:macro name="abb1" params="prefix">
    <!-- link list -->
    <link name="${prefix}base_link">
      <inertial>
        <mass value="0.6215"/>
        <origin xyz="-0.04204 8.01E-05 0.07964" rpy="0 0 0"/>
        <inertia ixx="0.00247272" ixy="-8.0784E-06" ixz="0.00130902e-1" iyy="0.0491285e-1" iyz="-8.0419e-7" izz="0.0472376e-1"/>
      </inertial>
      <visual>
        <origin xyz="0 0 0" rpy="0 0 0"/>
        <geometry>
          <mesh filename="package://husky_abb_description/meshes/abb/visual/base_link.stl"/>
        </geometry>
        <xacro:material_abb_orange />
      </visual>
      <!--<collision>
        <origin xyz="0 0 0" rpy="0 0 0"/>
        <geometry>
          <mesh filename="package://husky_abb_description/meshes/abb/collision/base_link.stl"/>
        </geometry>
        <xacro:material_abb_yellow />
      </collision>-->
    </link>
    <link name="${prefix}link_1">
      <inertial>
        <mass value="3.067e-1" />
        <origin xyz="9.77E-05 -0.00012 0.23841" rpy="0 0 0"/>
        <inertia ixx="0.0142175e-1" ixy="-1.28579E-06" ixz="-2.31364E-06" iyy="0.0144041e-1" iyz="1.93404E-06" izz="0.0104533e-1"/>
      </inertial>
      <visual>
        <origin xyz="0 0 0" rpy="0 0 0"/>
        <geometry>
          <mesh filename="package://husky_abb_description/meshes/abb/visual/link_1.stl"/>
        </geometry>
        <xacro:material_abb_orange />
      </visual>
      <!--<collision>
        <origin xyz="0 0 0" rpy="0 0 0"/>
        <geometry>
          <mesh filename="package://husky_abb_description/meshes/abb/collision/link_1.stl"/>
        </geometry>
        <xacro:material_abb_yellow />
      </collision>-->
    </link>
    <link name="${prefix}link_2">
      <inertial>
        <mass value="3.909e-1"/>
        <origin xyz="0.00078 -0.00212 0.10124" rpy="0 0 0"/>
        <inertia ixx="0.0603111e-1" ixy="9.83431E-07" ixz="5.72407E-06" iyy="0.041569e-1" iyz="-0.00050497e-1" izz="0.0259548e-1"/>     
      </inertial>
      <visual>
        <origin xyz="0 0 0" rpy="0 0 0"/>
        <geometry>
          <mesh filename="package://husky_abb_description/meshes/abb/visual/link_2.stl"/>
        </geometry>
        <xacro:material_abb_orange />
      </visual>
      <!--<collision>
        <origin xyz="0 0 0" rpy="0 0 0"/>
        <geometry>
          <mesh filename="package://husky_abb_description/meshes/abb/collision/link_2.stl"/>
        </geometry>
        <xacro:material_abb_yellow />
      </collision>-->
    </link>
    <link name="${prefix}link_3">
      <inertial>
        <mass value="2.944e-1"/>
        <origin xyz="0.02281 0.00106 0.05791" rpy="0 0 0"/>
        <inertia ixx="0.00835606e-1" ixy="-8.01545E-06" ixz="0.00142884e-1" iyy="0.016713e-1" iyz="-0.000182227e-1" izz="0.0126984e-1"/>
      </inertial>
      <visual>
        <origin xyz="0 0 0" rpy="0 0 0"/>
        <geometry>
          <mesh filename="package://husky_abb_description/meshes/abb/visual/link_3.stl"/>
        </geometry>
        <xacro:material_abb_orange />
      </visual>
      <!--<collision>
        <origin xyz="0 0 0" rpy="0 0 0"/>
        <geometry>
          <mesh filename="package://husky_abb_description/meshes/abb/collision/link_3.stl"/>
        </geometry>
        <xacro:material_abb_yellow />
      </collision>-->
    </link>
    <link name="${prefix}link_4">
      <inertial>
        <mass value="1.328e-1"/>
        <origin xyz="0.2247 0.00015 0.00041" rpy="0 0 0"/>
        <inertia ixx="0.00284661e-1" ixy="-2.12765E-06" ixz="-1.6435E-06" iyy="0.00401346e-1" iyz="1.31336E-06" izz="0.0052535e-1"/>
      </inertial>
      <visual>
        <origin xyz="0 0 0" rpy="0 0 0"/>
        <geometry>
          <mesh filename="package://husky_abb_description/meshes/abb/visual/link_4.stl"/>
        </geometry>
        <xacro:material_abb_orange />
      </visual>
      <!--<collision>
        <origin xyz="0 0 0" rpy="0 0 0"/>
        <geometry>
          <mesh filename="package://husky_abb_description/meshes/abb/collision/link_4.stl"/>
        </geometry>
        <xacro:material_abb_yellow />
      </collision>-->
    </link>
    <link name="${prefix}link_5">
      <inertial>
        <mass value="0.546e-1"/>
        <origin xyz="-0.00109 3.68E-05 6.22E-05" rpy="0 0 0"/>
        <inertia ixx="0.000404891e-1" ixy="1.61943E-07" ixz="8.46805E-08" iyy="0.000892825e-1" iyz="-1.51792E-09" izz="0.000815468e-1"/>
      </inertial>
      <visual>
        <origin xyz="0 0 0" rpy="0 0 0"/>
        <geometry>
          <mesh filename="package://husky_abb_description/meshes/abb/visual/link_5.stl"/>
        </geometry>
        <xacro:material_abb_orange />
      </visual>
      <!--<collision>
        <origin xyz="0 0 0" rpy="0 0 0"/>
        <geometry>
          <mesh filename="package://husky_abb_description/meshes/abb/collision/link_5.stl"/>
        </geometry>
        <xacro:material_abb_yellow />
      </collision>-->
    </link>
    <link name="${prefix}link_6">
      <inertial>
        <mass value="0.137e-1"/>
        <origin xyz="-0.00706 -0.00017 -1.32E-06" rpy="0 0 0"/>
        <inertia ixx="0.001e-1" ixy="0" ixz="0" iyy="0.001e-1" iyz="0" izz="0.001e-1"/>
      </inertial>
      <visual>
        <origin xyz="0 0 0" rpy="0 0 0"/>
        <geometry>
          <mesh filename="package://husky_abb_description/meshes/abb/visual/link_6.stl"/>
        </geometry>
        <xacro:material_abb_black />
      </visual>
      <!--<collision>
        <origin xyz="0 0 0" rpy="0 0 0"/>
        <geometry>
          <mesh filename="package://husky_abb_description/meshes/abb/collision/link_6.stl"/>
        </geometry>
        <xacro:material_abb_yellow />
      </collision>-->
    </link>
    <link name="${prefix}tool0"/>
    <!-- end of link list -->
    <joint name="${prefix}joint_1" type="revolute">
      <origin rpy="0 0 0" xyz="0 0 0"/>
      <parent link="${prefix}base_link"/>
      <child link="${prefix}link_1"/>
      <limit effort="0" lower="-2.87979" upper="2.87979" velocity="4.36332"/>
      <axis xyz="0 0 1"/>
      <dynamics damping="0.0" friction="0.0"/>
    </joint>
    <joint name="${prefix}joint_2" type="revolute">
      <origin rpy="0 0 0" xyz="0 0 0.29"/>
      <parent link="${prefix}link_1"/>
      <child link="${prefix}link_2"/>
      <limit effort="0" lower="-1.91986" upper="1.91986" velocity="4.36332"/>
      <axis xyz="0 1 0"/>
      <dynamics damping="0.0" friction="0.0"/>
    </joint>
    <joint name="${prefix}joint_3" type="revolute">
      <origin rpy="0 0 0" xyz="0 0 0.27"/>
      <!--origin rpy="0 0 0" xyz="0 0 0.27"/-->
      <parent link="${prefix}link_2"/>
      <child link="${prefix}link_3"/>
      <limit effort="0" lower="-1.91986" upper="1.22173" velocity="4.36332"/>
      <axis xyz="0 1 0"/>
      <dynamics damping="0.0" friction="0.0"/>
    </joint>
    <joint name="${prefix}joint_4" type="revolute">
      <origin rpy="0 0 0" xyz="0 0 0.07"/>
      <parent link="${prefix}link_3"/>
      <child link="${prefix}link_4"/>
      <limit effort="0" lower="-2.79253" upper="2.79253" velocity="5.58505"/>
      <axis xyz="1 0 0"/>
      <dynamics damping="0.0" friction="0.0"/>
    </joint>
    <joint name="${prefix}joint_5" type="revolute">
      <origin rpy="0 0 0" xyz="0.302 0 0"/>
      <parent link="${prefix}link_4"/>
      <child link="${prefix}link_5"/>
      <limit effort="0" lower="-2.094395" upper="2.094395" velocity="5.58505"/>
      <axis xyz="0 1 0"/>
      <dynamics damping="0.0" friction="0.0"/>
    </joint>
    <joint name="${prefix}joint_6" type="revolute">
      <origin rpy="0 0 0" xyz="0.072 0 0"/>
      <parent link="${prefix}link_5"/>
      <child link="${prefix}link_6"/>
      <limit effort="0" lower="-6.98132" upper="6.98132" velocity="7.33038"/>
      <axis xyz="1 0 0"/>
      <dynamics damping="0.0" friction="0.0"/>
    </joint>
    <joint name="${prefix}joint6-tool0" type="fixed">
      <parent link="${prefix}link_6"/>
      <child link="${prefix}tool0"/>
      <origin rpy="0 0 0" xyz="0 0 0"/>
    </joint>
    <!-- end of joint list -->

    <!-- ROS base_link to ABB World Coordinates transform -->
    <link name="${prefix}base" />
    <joint name="${prefix}base_link-base" type="fixed">
      <origin xyz="0 0 0" rpy="0 0 0"/>
      <parent link="${prefix}base_link"/>
      <child link="${prefix}base"/>
    </joint>
  </xacro:macro>
</robot>